[2024-02-13T02:51:44.395+0000] {taskinstance.py:1956} INFO - Dependencies all met for dep_context=non-requeueable deps ti=<TaskInstance: our_dag_with_python_operator_v4.greet manual__2024-02-13T02:51:41.942014+00:00 [queued]>
[2024-02-13T02:51:44.436+0000] {taskinstance.py:1956} INFO - Dependencies all met for dep_context=requeueable deps ti=<TaskInstance: our_dag_with_python_operator_v4.greet manual__2024-02-13T02:51:41.942014+00:00 [queued]>
[2024-02-13T02:51:44.437+0000] {taskinstance.py:2170} INFO - Starting attempt 1 of 6
[2024-02-13T02:51:44.479+0000] {taskinstance.py:2191} INFO - Executing <Task(PythonOperator): greet> on 2024-02-13 02:51:41.942014+00:00
[2024-02-13T02:51:44.492+0000] {standard_task_runner.py:60} INFO - Started process 190 to run task
[2024-02-13T02:51:44.506+0000] {standard_task_runner.py:87} INFO - Running: ['***', 'tasks', 'run', 'our_dag_with_python_operator_v4', 'greet', 'manual__2024-02-13T02:51:41.942014+00:00', '--job-id', '26', '--raw', '--subdir', 'DAGS_FOLDER/create_dag_with_python_operator.py', '--cfg-path', '/tmp/tmpisl4fu68']
[2024-02-13T02:51:44.507+0000] {standard_task_runner.py:88} INFO - Job 26: Subtask greet
[2024-02-13T02:51:44.580+0000] {task_command.py:423} INFO - Running <TaskInstance: our_dag_with_python_operator_v4.greet manual__2024-02-13T02:51:41.942014+00:00 [running]> on host e97f82a89325
[2024-02-13T02:51:44.727+0000] {taskinstance.py:2480} INFO - Exporting env vars: AIRFLOW_CTX_DAG_OWNER='shiv' AIRFLOW_CTX_DAG_ID='our_dag_with_python_operator_v4' AIRFLOW_CTX_TASK_ID='greet' AIRFLOW_CTX_EXECUTION_DATE='2024-02-13T02:51:41.942014+00:00' AIRFLOW_CTX_TRY_NUMBER='1' AIRFLOW_CTX_DAG_RUN_ID='manual__2024-02-13T02:51:41.942014+00:00'
[2024-02-13T02:51:44.728+0000] {taskinstance.py:2698} ERROR - Task failed with exception
Traceback (most recent call last):
  File "/home/airflow/.local/lib/python3.8/site-packages/airflow/models/taskinstance.py", line 433, in _execute_task
    result = execute_callable(context=context, **execute_callable_kwargs)
  File "/home/airflow/.local/lib/python3.8/site-packages/airflow/operators/python.py", line 199, in execute
    return_value = self.execute_callable()
  File "/home/airflow/.local/lib/python3.8/site-packages/airflow/operators/python.py", line 216, in execute_callable
    return self.python_callable(*self.op_args, **self.op_kwargs)
  File "/opt/airflow/dags/create_dag_with_python_operator.py", line 12, in greet
    name = ti.xcoms_pull(task_ids='get_name')
AttributeError: 'TaskInstance' object has no attribute 'xcoms_pull'
[2024-02-13T02:51:44.742+0000] {taskinstance.py:1138} INFO - Marking task as UP_FOR_RETRY. dag_id=our_dag_with_python_operator_v4, task_id=greet, execution_date=20240213T025141, start_date=20240213T025144, end_date=20240213T025144
[2024-02-13T02:51:44.777+0000] {standard_task_runner.py:107} ERROR - Failed to execute job 26 for task greet ('TaskInstance' object has no attribute 'xcoms_pull'; 190)
[2024-02-13T02:51:44.803+0000] {local_task_job_runner.py:234} INFO - Task exited with return code 1
[2024-02-13T02:51:44.816+0000] {taskinstance.py:3280} INFO - 0 downstream tasks scheduled from follow-on schedule check
