[2024-02-28T04:13:11.827+0000] {taskinstance.py:1956} INFO - Dependencies all met for dep_context=non-requeueable deps ti=<TaskInstance: dag_with_minio_s3_v03.sensor_minio_s3 manual__2024-02-28T03:52:28.291441+00:00 [queued]>
[2024-02-28T04:13:11.833+0000] {taskinstance.py:1956} INFO - Dependencies all met for dep_context=requeueable deps ti=<TaskInstance: dag_with_minio_s3_v03.sensor_minio_s3 manual__2024-02-28T03:52:28.291441+00:00 [queued]>
[2024-02-28T04:13:11.834+0000] {taskinstance.py:2170} INFO - Starting attempt 5 of 6
[2024-02-28T04:13:11.847+0000] {taskinstance.py:2191} INFO - Executing <Task(S3KeySensor): sensor_minio_s3> on 2024-02-28 03:52:28.291441+00:00
[2024-02-28T04:13:11.854+0000] {standard_task_runner.py:60} INFO - Started process 665 to run task
[2024-02-28T04:13:11.857+0000] {standard_task_runner.py:87} INFO - Running: ['***', 'tasks', 'run', 'dag_with_minio_s3_v03', 'sensor_minio_s3', 'manual__2024-02-28T03:52:28.291441+00:00', '--job-id', '573', '--raw', '--subdir', 'DAGS_FOLDER/dag_with_minio_s3.py', '--cfg-path', '/tmp/tmpwzc10ga1']
[2024-02-28T04:13:11.858+0000] {standard_task_runner.py:88} INFO - Job 573: Subtask sensor_minio_s3
[2024-02-28T04:13:11.898+0000] {task_command.py:423} INFO - Running <TaskInstance: dag_with_minio_s3_v03.sensor_minio_s3 manual__2024-02-28T03:52:28.291441+00:00 [running]> on host ce0c9f4015d1
[2024-02-28T04:13:11.957+0000] {taskinstance.py:2480} INFO - Exporting env vars: AIRFLOW_CTX_DAG_OWNER='Shiv' AIRFLOW_CTX_DAG_ID='dag_with_minio_s3_v03' AIRFLOW_CTX_TASK_ID='sensor_minio_s3' AIRFLOW_CTX_EXECUTION_DATE='2024-02-28T03:52:28.291441+00:00' AIRFLOW_CTX_TRY_NUMBER='5' AIRFLOW_CTX_DAG_RUN_ID='manual__2024-02-28T03:52:28.291441+00:00'
[2024-02-28T04:13:11.958+0000] {s3.py:106} INFO - Poking for key : s3://***/data.csv
[2024-02-28T04:13:11.965+0000] {base.py:83} INFO - Using connection ID 'minio_s3_conn' for task execution.
[2024-02-28T04:13:13.090+0000] {taskinstance.py:2698} ERROR - Task failed with exception
Traceback (most recent call last):
  File "/home/airflow/.local/lib/python3.8/site-packages/airflow/models/taskinstance.py", line 433, in _execute_task
    result = execute_callable(context=context, **execute_callable_kwargs)
  File "/home/airflow/.local/lib/python3.8/site-packages/airflow/providers/amazon/aws/sensors/s3.py", line 144, in execute
    super().execute(context)
  File "/home/airflow/.local/lib/python3.8/site-packages/airflow/sensors/base.py", line 265, in execute
    raise e
  File "/home/airflow/.local/lib/python3.8/site-packages/airflow/sensors/base.py", line 247, in execute
    poke_return = self.poke(context)
  File "/home/airflow/.local/lib/python3.8/site-packages/airflow/providers/amazon/aws/sensors/s3.py", line 137, in poke
    return self._check_key(self.bucket_key)
  File "/home/airflow/.local/lib/python3.8/site-packages/airflow/providers/amazon/aws/sensors/s3.py", line 125, in _check_key
    obj = self.hook.head_object(key, bucket_name)
  File "/home/airflow/.local/lib/python3.8/site-packages/airflow/providers/amazon/aws/hooks/s3.py", line 137, in wrapper
    return func(*bound_args.args, **bound_args.kwargs)
  File "/home/airflow/.local/lib/python3.8/site-packages/airflow/providers/amazon/aws/hooks/s3.py", line 91, in wrapper
    return func(*bound_args.args, **bound_args.kwargs)
  File "/home/airflow/.local/lib/python3.8/site-packages/airflow/providers/amazon/aws/hooks/s3.py", line 892, in head_object
    raise e
  File "/home/airflow/.local/lib/python3.8/site-packages/airflow/providers/amazon/aws/hooks/s3.py", line 887, in head_object
    return self.get_conn().head_object(Bucket=bucket_name, Key=key)
  File "/home/airflow/.local/lib/python3.8/site-packages/botocore/client.py", line 553, in _api_call
    return self._make_api_call(operation_name, kwargs)
  File "/home/airflow/.local/lib/python3.8/site-packages/botocore/client.py", line 1009, in _make_api_call
    raise error_class(parsed_response, operation_name)
botocore.exceptions.ClientError: An error occurred (403) when calling the HeadObject operation: Forbidden
[2024-02-28T04:13:13.100+0000] {taskinstance.py:1138} INFO - Marking task as UP_FOR_RETRY. dag_id=dag_with_minio_s3_v03, task_id=sensor_minio_s3, execution_date=20240228T035228, start_date=20240228T041311, end_date=20240228T041313
[2024-02-28T04:13:13.150+0000] {standard_task_runner.py:107} ERROR - Failed to execute job 573 for task sensor_minio_s3 (An error occurred (403) when calling the HeadObject operation: Forbidden; 665)
[2024-02-28T04:13:13.221+0000] {local_task_job_runner.py:234} INFO - Task exited with return code 1
[2024-02-28T04:13:13.245+0000] {taskinstance.py:3280} INFO - 0 downstream tasks scheduled from follow-on schedule check
