[2024-02-16T16:37:25.379+0000] {taskinstance.py:1956} INFO - Dependencies all met for dep_context=non-requeueable deps ti=<TaskInstance: dag_with_catchup_backup_v2.task1 manual__2024-02-16T16:37:21.466665+00:00 [queued]>
[2024-02-16T16:37:25.409+0000] {taskinstance.py:1956} INFO - Dependencies all met for dep_context=requeueable deps ti=<TaskInstance: dag_with_catchup_backup_v2.task1 manual__2024-02-16T16:37:21.466665+00:00 [queued]>
[2024-02-16T16:37:25.410+0000] {taskinstance.py:2170} INFO - Starting attempt 1 of 6
[2024-02-16T16:37:25.483+0000] {taskinstance.py:2191} INFO - Executing <Task(BashOperator): task1> on 2024-02-16 16:37:21.466665+00:00
[2024-02-16T16:37:25.516+0000] {standard_task_runner.py:60} INFO - Started process 196 to run task
[2024-02-16T16:37:25.544+0000] {standard_task_runner.py:87} INFO - Running: ['***', 'tasks', 'run', 'dag_with_catchup_backup_v2', 'task1', 'manual__2024-02-16T16:37:21.466665+00:00', '--job-id', '397', '--raw', '--subdir', 'DAGS_FOLDER/dag_with_catchup_backfill.py', '--cfg-path', '/tmp/tmpur5clf_x']
[2024-02-16T16:37:25.546+0000] {standard_task_runner.py:88} INFO - Job 397: Subtask task1
[2024-02-16T16:37:25.741+0000] {task_command.py:423} INFO - Running <TaskInstance: dag_with_catchup_backup_v2.task1 manual__2024-02-16T16:37:21.466665+00:00 [running]> on host 7c2825a65d38
[2024-02-16T16:37:26.429+0000] {taskinstance.py:2480} INFO - Exporting env vars: AIRFLOW_CTX_DAG_OWNER='Shiv' AIRFLOW_CTX_DAG_ID='dag_with_catchup_backup_v2' AIRFLOW_CTX_TASK_ID='task1' AIRFLOW_CTX_EXECUTION_DATE='2024-02-16T16:37:21.466665+00:00' AIRFLOW_CTX_TRY_NUMBER='1' AIRFLOW_CTX_DAG_RUN_ID='manual__2024-02-16T16:37:21.466665+00:00'
[2024-02-16T16:37:26.446+0000] {subprocess.py:63} INFO - Tmp dir root location: /tmp
[2024-02-16T16:37:26.450+0000] {subprocess.py:75} INFO - Running command: ['/usr/bin/bash', '-c', 'echo Yellow, this is bash command being bashing around']
[2024-02-16T16:37:26.656+0000] {subprocess.py:86} INFO - Output:
[2024-02-16T16:37:26.678+0000] {subprocess.py:93} INFO - Yellow, this is bash command being bashing around
[2024-02-16T16:37:26.693+0000] {subprocess.py:97} INFO - Command exited with return code 0
[2024-02-16T16:37:26.854+0000] {taskinstance.py:1138} INFO - Marking task as SUCCESS. dag_id=dag_with_catchup_backup_v2, task_id=task1, execution_date=20240216T163721, start_date=20240216T163725, end_date=20240216T163726
[2024-02-16T16:37:27.010+0000] {local_task_job_runner.py:234} INFO - Task exited with return code 0
[2024-02-16T16:37:27.072+0000] {taskinstance.py:3280} INFO - 0 downstream tasks scheduled from follow-on schedule check
