[2024-02-28T03:52:29.362+0000] {taskinstance.py:1956} INFO - Dependencies all met for dep_context=non-requeueable deps ti=<TaskInstance: dag_with_minio_s3_v03.sensor_minio_s3 scheduled__2024-02-24T00:00:00+00:00 [queued]>
[2024-02-28T03:52:29.432+0000] {taskinstance.py:1956} INFO - Dependencies all met for dep_context=requeueable deps ti=<TaskInstance: dag_with_minio_s3_v03.sensor_minio_s3 scheduled__2024-02-24T00:00:00+00:00 [queued]>
[2024-02-28T03:52:29.433+0000] {taskinstance.py:2170} INFO - Starting attempt 1 of 6
[2024-02-28T03:52:29.594+0000] {taskinstance.py:2191} INFO - Executing <Task(S3KeySensor): sensor_minio_s3> on 2024-02-24 00:00:00+00:00
[2024-02-28T03:52:29.648+0000] {standard_task_runner.py:60} INFO - Started process 295 to run task
[2024-02-28T03:52:29.710+0000] {standard_task_runner.py:87} INFO - Running: ['***', 'tasks', 'run', 'dag_with_minio_s3_v03', 'sensor_minio_s3', 'scheduled__2024-02-24T00:00:00+00:00', '--job-id', '545', '--raw', '--subdir', 'DAGS_FOLDER/dag_with_minio_s3.py', '--cfg-path', '/tmp/tmpyl4r7pdc']
[2024-02-28T03:52:29.752+0000] {standard_task_runner.py:88} INFO - Job 545: Subtask sensor_minio_s3
[2024-02-28T03:52:30.044+0000] {task_command.py:423} INFO - Running <TaskInstance: dag_with_minio_s3_v03.sensor_minio_s3 scheduled__2024-02-24T00:00:00+00:00 [running]> on host ce0c9f4015d1
[2024-02-28T03:52:30.366+0000] {taskinstance.py:2480} INFO - Exporting env vars: AIRFLOW_CTX_DAG_OWNER='Shiv' AIRFLOW_CTX_DAG_ID='dag_with_minio_s3_v03' AIRFLOW_CTX_TASK_ID='sensor_minio_s3' AIRFLOW_CTX_EXECUTION_DATE='2024-02-24T00:00:00+00:00' AIRFLOW_CTX_TRY_NUMBER='1' AIRFLOW_CTX_DAG_RUN_ID='scheduled__2024-02-24T00:00:00+00:00'
[2024-02-28T03:52:30.367+0000] {s3.py:106} INFO - Poking for key : s3://***/data.csv
[2024-02-28T03:52:30.413+0000] {base.py:83} INFO - Using connection ID 'minio_s3_conn' for task execution.
[2024-02-28T03:52:43.267+0000] {taskinstance.py:2698} ERROR - Task failed with exception
Traceback (most recent call last):
  File "/home/airflow/.local/lib/python3.8/site-packages/urllib3/connection.py", line 174, in _new_conn
    conn = connection.create_connection(
  File "/home/airflow/.local/lib/python3.8/site-packages/urllib3/util/connection.py", line 72, in create_connection
    for res in socket.getaddrinfo(host, port, family, socket.SOCK_STREAM):
  File "/usr/local/lib/python3.8/socket.py", line 918, in getaddrinfo
    for res in _socket.getaddrinfo(host, port, family, type, proto, flags):
socket.gaierror: [Errno -2] Name or service not known

During handling of the above exception, another exception occurred:

Traceback (most recent call last):
  File "/home/airflow/.local/lib/python3.8/site-packages/botocore/httpsession.py", line 464, in send
    urllib_response = conn.urlopen(
  File "/home/airflow/.local/lib/python3.8/site-packages/urllib3/connectionpool.py", line 799, in urlopen
    retries = retries.increment(
  File "/home/airflow/.local/lib/python3.8/site-packages/urllib3/util/retry.py", line 525, in increment
    raise six.reraise(type(error), error, _stacktrace)
  File "/home/airflow/.local/lib/python3.8/site-packages/urllib3/packages/six.py", line 770, in reraise
    raise value
  File "/home/airflow/.local/lib/python3.8/site-packages/urllib3/connectionpool.py", line 715, in urlopen
    httplib_response = self._make_request(
  File "/home/airflow/.local/lib/python3.8/site-packages/urllib3/connectionpool.py", line 416, in _make_request
    conn.request(method, url, **httplib_request_kw)
  File "/home/airflow/.local/lib/python3.8/site-packages/botocore/awsrequest.py", line 96, in request
    rval = super().request(method, url, body, headers, *args, **kwargs)
  File "/home/airflow/.local/lib/python3.8/site-packages/urllib3/connection.py", line 244, in request
    super(HTTPConnection, self).request(method, url, body=body, headers=headers)
  File "/usr/local/lib/python3.8/http/client.py", line 1256, in request
    self._send_request(method, url, body, headers, encode_chunked)
  File "/usr/local/lib/python3.8/http/client.py", line 1302, in _send_request
    self.endheaders(body, encode_chunked=encode_chunked)
  File "/usr/local/lib/python3.8/http/client.py", line 1251, in endheaders
    self._send_output(message_body, encode_chunked=encode_chunked)
  File "/home/airflow/.local/lib/python3.8/site-packages/botocore/awsrequest.py", line 123, in _send_output
    self.send(msg)
  File "/home/airflow/.local/lib/python3.8/site-packages/botocore/awsrequest.py", line 223, in send
    return super().send(str)
  File "/usr/local/lib/python3.8/http/client.py", line 951, in send
    self.connect()
  File "/home/airflow/.local/lib/python3.8/site-packages/urllib3/connection.py", line 205, in connect
    conn = self._new_conn()
  File "/home/airflow/.local/lib/python3.8/site-packages/urllib3/connection.py", line 186, in _new_conn
    raise NewConnectionError(
urllib3.exceptions.NewConnectionError: <botocore.awsrequest.AWSHTTPConnection object at 0x7f3f88b402b0>: Failed to establish a new connection: [Errno -2] Name or service not known

During handling of the above exception, another exception occurred:

Traceback (most recent call last):
  File "/home/airflow/.local/lib/python3.8/site-packages/airflow/models/taskinstance.py", line 433, in _execute_task
    result = execute_callable(context=context, **execute_callable_kwargs)
  File "/home/airflow/.local/lib/python3.8/site-packages/airflow/providers/amazon/aws/sensors/s3.py", line 144, in execute
    super().execute(context)
  File "/home/airflow/.local/lib/python3.8/site-packages/airflow/sensors/base.py", line 265, in execute
    raise e
  File "/home/airflow/.local/lib/python3.8/site-packages/airflow/sensors/base.py", line 247, in execute
    poke_return = self.poke(context)
  File "/home/airflow/.local/lib/python3.8/site-packages/airflow/providers/amazon/aws/sensors/s3.py", line 137, in poke
    return self._check_key(self.bucket_key)
  File "/home/airflow/.local/lib/python3.8/site-packages/airflow/providers/amazon/aws/sensors/s3.py", line 125, in _check_key
    obj = self.hook.head_object(key, bucket_name)
  File "/home/airflow/.local/lib/python3.8/site-packages/airflow/providers/amazon/aws/hooks/s3.py", line 137, in wrapper
    return func(*bound_args.args, **bound_args.kwargs)
  File "/home/airflow/.local/lib/python3.8/site-packages/airflow/providers/amazon/aws/hooks/s3.py", line 91, in wrapper
    return func(*bound_args.args, **bound_args.kwargs)
  File "/home/airflow/.local/lib/python3.8/site-packages/airflow/providers/amazon/aws/hooks/s3.py", line 887, in head_object
    return self.get_conn().head_object(Bucket=bucket_name, Key=key)
  File "/home/airflow/.local/lib/python3.8/site-packages/botocore/client.py", line 553, in _api_call
    return self._make_api_call(operation_name, kwargs)
  File "/home/airflow/.local/lib/python3.8/site-packages/botocore/client.py", line 989, in _make_api_call
    http, parsed_response = self._make_request(
  File "/home/airflow/.local/lib/python3.8/site-packages/botocore/client.py", line 1015, in _make_request
    return self._endpoint.make_request(operation_model, request_dict)
  File "/home/airflow/.local/lib/python3.8/site-packages/botocore/endpoint.py", line 119, in make_request
    return self._send_request(request_dict, operation_model)
  File "/home/airflow/.local/lib/python3.8/site-packages/botocore/endpoint.py", line 202, in _send_request
    while self._needs_retry(
  File "/home/airflow/.local/lib/python3.8/site-packages/botocore/endpoint.py", line 354, in _needs_retry
    responses = self._event_emitter.emit(
  File "/home/airflow/.local/lib/python3.8/site-packages/botocore/hooks.py", line 412, in emit
    return self._emitter.emit(aliased_event_name, **kwargs)
  File "/home/airflow/.local/lib/python3.8/site-packages/botocore/hooks.py", line 256, in emit
    return self._emit(event_name, kwargs)
  File "/home/airflow/.local/lib/python3.8/site-packages/botocore/hooks.py", line 239, in _emit
    response = handler(**kwargs)
  File "/home/airflow/.local/lib/python3.8/site-packages/botocore/retryhandler.py", line 207, in __call__
    if self._checker(**checker_kwargs):
  File "/home/airflow/.local/lib/python3.8/site-packages/botocore/retryhandler.py", line 284, in __call__
    should_retry = self._should_retry(
  File "/home/airflow/.local/lib/python3.8/site-packages/botocore/retryhandler.py", line 320, in _should_retry
    return self._checker(attempt_number, response, caught_exception)
  File "/home/airflow/.local/lib/python3.8/site-packages/botocore/retryhandler.py", line 363, in __call__
    checker_response = checker(
  File "/home/airflow/.local/lib/python3.8/site-packages/botocore/retryhandler.py", line 247, in __call__
    return self._check_caught_exception(
  File "/home/airflow/.local/lib/python3.8/site-packages/botocore/retryhandler.py", line 416, in _check_caught_exception
    raise caught_exception
  File "/home/airflow/.local/lib/python3.8/site-packages/botocore/endpoint.py", line 281, in _do_get_response
    http_response = self._send(request)
  File "/home/airflow/.local/lib/python3.8/site-packages/botocore/endpoint.py", line 377, in _send
    return self.http_session.send(request)
  File "/home/airflow/.local/lib/python3.8/site-packages/botocore/httpsession.py", line 493, in send
    raise EndpointConnectionError(endpoint_url=request.url, error=e)
botocore.exceptions.EndpointConnectionError: Could not connect to the endpoint URL: "http://host.docker.internal:9000/***/data.csv"
[2024-02-28T03:52:43.276+0000] {taskinstance.py:1138} INFO - Marking task as UP_FOR_RETRY. dag_id=dag_with_minio_s3_v03, task_id=sensor_minio_s3, execution_date=20240224T000000, start_date=20240228T035229, end_date=20240228T035243
[2024-02-28T03:52:43.298+0000] {standard_task_runner.py:107} ERROR - Failed to execute job 545 for task sensor_minio_s3 (Could not connect to the endpoint URL: "http://host.docker.internal:9000/***/data.csv"; 295)
[2024-02-28T03:52:43.353+0000] {local_task_job_runner.py:234} INFO - Task exited with return code 1
[2024-02-28T03:52:43.364+0000] {taskinstance.py:3280} INFO - 0 downstream tasks scheduled from follow-on schedule check
