[2024-02-16T16:47:04.012+0000] {taskinstance.py:1956} INFO - Dependencies all met for dep_context=non-requeueable deps ti=<TaskInstance: dag_with_catchup_backup_v3.task1 backfill__2024-02-07T00:00:00+00:00 [queued]>
[2024-02-16T16:47:04.122+0000] {taskinstance.py:1956} INFO - Dependencies all met for dep_context=requeueable deps ti=<TaskInstance: dag_with_catchup_backup_v3.task1 backfill__2024-02-07T00:00:00+00:00 [queued]>
[2024-02-16T16:47:04.123+0000] {taskinstance.py:2170} INFO - Starting attempt 1 of 6
[2024-02-16T16:47:04.211+0000] {taskinstance.py:2191} INFO - Executing <Task(BashOperator): task1> on 2024-02-07 00:00:00+00:00
[2024-02-16T16:47:04.249+0000] {standard_task_runner.py:60} INFO - Started process 367 to run task
[2024-02-16T16:47:04.293+0000] {standard_task_runner.py:87} INFO - Running: ['***', 'tasks', 'run', 'dag_with_catchup_backup_v3', 'task1', 'backfill__2024-02-07T00:00:00+00:00', '--job-id', '407', '--pool', 'default_pool', '--raw', '--subdir', 'DAGS_FOLDER/dag_with_catchup_backfill.py', '--cfg-path', '/tmp/tmp0eqiay8q']
[2024-02-16T16:47:04.294+0000] {standard_task_runner.py:88} INFO - Job 407: Subtask task1
[2024-02-16T16:47:04.663+0000] {task_command.py:423} INFO - Running <TaskInstance: dag_with_catchup_backup_v3.task1 backfill__2024-02-07T00:00:00+00:00 [running]> on host 7c2825a65d38
[2024-02-16T16:47:05.328+0000] {taskinstance.py:2480} INFO - Exporting env vars: AIRFLOW_CTX_DAG_OWNER='Shiv' AIRFLOW_CTX_DAG_ID='dag_with_catchup_backup_v3' AIRFLOW_CTX_TASK_ID='task1' AIRFLOW_CTX_EXECUTION_DATE='2024-02-07T00:00:00+00:00' AIRFLOW_CTX_TRY_NUMBER='1' AIRFLOW_CTX_DAG_RUN_ID='backfill__2024-02-07T00:00:00+00:00'
[2024-02-16T16:47:05.335+0000] {subprocess.py:63} INFO - Tmp dir root location: /tmp
[2024-02-16T16:47:05.339+0000] {subprocess.py:75} INFO - Running command: ['/usr/bin/bash', '-c', 'echo Yellow, this is bash command being bashing around']
[2024-02-16T16:47:05.430+0000] {subprocess.py:86} INFO - Output:
[2024-02-16T16:47:05.434+0000] {subprocess.py:93} INFO - Yellow, this is bash command being bashing around
[2024-02-16T16:47:05.444+0000] {subprocess.py:97} INFO - Command exited with return code 0
[2024-02-16T16:47:05.506+0000] {taskinstance.py:1138} INFO - Marking task as SUCCESS. dag_id=dag_with_catchup_backup_v3, task_id=task1, execution_date=20240207T000000, start_date=20240216T164704, end_date=20240216T164705
[2024-02-16T16:47:05.634+0000] {local_task_job_runner.py:234} INFO - Task exited with return code 0
[2024-02-16T16:47:05.668+0000] {taskinstance.py:3280} INFO - 0 downstream tasks scheduled from follow-on schedule check
